<?xml version="1.0" ?>
<robot name="rootModel">
    <link name="baseLink">
        <visual>
            <geometry>
                <sphere radius="0.1"/>
            </geometry>
            <material>
                <color rgba="0.2 0.7 0.9 1"/>
            </material>
            <origin rpy="0 0 0" xyz="0.1 0 0.3"/>
        </visual>
    </link>
    <joint name="jointC" type="revolute">
        <axis xyz="1 0 0"/>
        <origin rpy="0 0 0" xyz="0.1 0 0.0"/>
        <parent link="baseLink"/>
        <child link="head"/>
        <limit effort="190" lower="-1.1" upper="0.4141" velocity="5.89"/>
    </joint>
    <link name="head">
        <visual>
            <geometry>
                <sphere radius="0.1"/>
            </geometry>
            <material>
                <color rgba="0.2 0.7 0.9 1"/>
            </material>
            <origin rpy="0 0 0" xyz="0.1 0 0.3"/>
        </visual>
    </link>
</robot>